Workbook

Sheet Data
A1: Date | B1: Inflation | C1: Interest Rate | D1: M2 | E1: Industry Production | F1: Import | G1: Export | H1: USDPLN | I1: USD Reserves
A2: 38383 | B2: =Inflation!C2 -> 103.7 | C2: =LOOKUP(A2,inrtpl_m_m[Data],inrtpl_m_m[Zamkniecie2]) -> 6.5 | D2: 366416.96 | E2: ='Industry Production'!C2 -> 100 | F2: ='Import Export'!D2 -> 14440.8 | G2: ='Import Export'!E2 -> 9341.3 | H2: 3.1106 | I2: 40968.3
A3: 38411 | B3: =Inflation!C3 -> 103.6 | C3: =LOOKUP(A3,inrtpl_m_m[Data],inrtpl_m_m[Zamkniecie2]) -> 6.5 | D3: 371693.58 | E3: ='Industry Production'!C3 -> 100 | F3: ='Import Export'!D3 -> 16351.6 | G3: ='Import Export'!E3 -> 10647.4 | H3: 2.9384 | I3: 42535.8
A4: 38442 | B4: =Inflation!C4 -> 103.4 | C4: =LOOKUP(A4,inrtpl_m_m[Data],inrtpl_m_m[Zamkniecie2]) -> 6 | D4: 380308.27 | E4: ='Industry Production'!C4 -> 109.5 | F4: ='Import Export'!D4 -> 17884.3 | G4: ='Import Export'!E4 -> 11228.3 | H4: 3.1445 | I4: 38220.8
A5: 38472 | B5: =Inflation!C5 -> 103 | C5: =LOOKUP(A5,inrtpl_m_m[Data],inrtpl_m_m[Zamkniecie2]) -> 5.5 | D5: 385623.92 | E5: ='Industry Production'!C5 -> 99.1 | F5: ='Import Export'!D5 -> 16446.1 | G5: ='Import Export'!E5 -> 10471.2 | H5: 3.3087 | I5: 40773.6
A6: 38503 | B6: =Inflation!C6 -> 102.5 | C6: =LOOKUP(A6,inrtpl_m_m[Data],inrtpl_m_m[Zamkniecie2]) -> 5.5 | D6: 392122.96 | E6: ='Industry Production'!C6 -> 95.1 | F6: ='Import Export'!D6 -> 19171.6 | G6: ='Import Export'!E6 -> 10908.7 | H6: 3.3612 | I6: 40638
A7: 38533 | B7: =Inflation!C7 -> 101.4 | C7: =LOOKUP(A7,inrtpl_m_m[Data],inrtpl_m_m[Zamkniecie2]) -> 5 | D7: 390159.93 | E7: ='Industry Production'!C7 -> 108.7 | F7: ='Import Export'!D7 -> 17958.6 | G7: ='Import Export'!E7 -> 11470.9 | H7: 3.3431 | I7: 41237.2
A8: 38564 | B8: =Inflation!C8 -> 101.3 | C8: =LOOKUP(A8,inrtpl_m_m[Data],inrtpl_m_m[Zamkniecie2]) -> 4.75 | D8: 391150.42 | E8: ='Industry Production'!C8 -> 92.3 | F8: ='Import Export'!D8 -> 17786.4 | G8: ='Import Export'!E8 -> 11550.4 | H8: 3.3531 | I8: 40801.4
A9: 38595 | B9: =Inflation!C9 -> 101.6 | C9: =LOOKUP(A9,inrtpl_m_m[Data],inrtpl_m_m[Zamkniecie2]) -> 4.75 | D9: 397421.8 | E9: ='Industry Production'!C9 -> 104.1 | F9: ='Import Export'!D9 -> 16692.8 | G9: ='Import Export'!E9 -> 11193.9 | H9: 3.2707 | I9: 41338.4
A10: 38625 | B10: =Inflation!C10 -> 101.8 | C10: =LOOKUP(A10,inrtpl_m_m[Data],inrtpl_m_m[Zamkniecie2]) -> 4.5 | D10: 401581.22 | E10: ='Industry Production'!C10 -> 109.9 | F10: ='Import Export'!D10 -> 18052.1 | G10: ='Import Export'!E10 -> 12367.8 | H10: 3.2369 | I10: 41054.7
A11: 38656 | B11: =Inflation!C11 -> 101.6 | C11: =LOOKUP(A11,inrtpl_m_m[Data],inrtpl_m_m[Zamkniecie2]) -> 4.5 | D11: 407006.48 | E11: ='Industry Production'!C11 -> 101.8 | F11: ='Import Export'!D11 -> 20579.6 | G11: ='Import Export'!E11 -> 13605.1 | H11: 3.3074 | I11: 41679.5
A12: 38686 | B12: =Inflation!C12 -> 101 | C12: =LOOKUP(A12,inrtpl_m_m[Data],inrtpl_m_m[Zamkniecie2]) -> 4.5 | D12: 408782.11 | E12: ='Industry Production'!C12 -> 100 | F12: ='Import Export'!D12 -> 19130.9 | G12: ='Import Export'!E12 -> 13118.5 | H12: 3.3133 | I12: 41440.6
A13: 38717 | B13: =Inflation!C13 -> 100.7 | C13: =LOOKUP(A13,inrtpl_m_m[Data],inrtpl_m_m[Zamkniecie2]) -> 4.5 | D13: 415163.52 | E13: ='Industry Production'!C13 -> 98.2 | F13: ='Import Export'!D13 -> 18577 | G13: ='Import Export'!E13 -> 12005.2 | H13: 3.2447 | I13: 42571.2
... A241: 45657 | B241: =Inflation!C241 -> 104.7 | C241: =LOOKUP(A241,inrtpl_m_m[Data],inrtpl_m_m[Zamkniecie2]) -> 5.75 | D241: 2469096.4 | E241: ='Industry Production'!C241 -> 92.1 | F241: ='Import Export'!D241 -> 77610.1 | G241: ='Import Export'!E241 -> 77145.2 | H241: 4.12993 | I241: 223166.4

Sheet Inflation
A1: Data | B1: Inflation | C1: Inflation
A2: 38383 | B2: 103,7 | C2: =B2*1 -> 103.7
A3: 38411 | B3: 103,6 | C3: =B3*1 -> 103.6
A4: 38442 | B4: 103,4 | C4: =B4*1 -> 103.4
A5: 38472 | B5: 103,0 | C5: =B5*1 -> 103
A6: 38503 | B6: 102,5 | C6: =B6*1 -> 102.5
A7: 38533 | B7: 101,4 | C7: =B7*1 -> 101.4
A8: 38564 | B8: 101,3 | C8: =B8*1 -> 101.3
A9: 38595 | B9: 101,6 | C9: =B9*1 -> 101.6
A10: 38625 | B10: 101,8 | C10: =B10*1 -> 101.8
A11: 38656 | B11: 101,6 | C11: =B11*1 -> 101.6
A12: 38686 | B12: 101,0 | C12: =B12*1 -> 101
A13: 38717 | B13: 100,7 | C13: =B13*1 -> 100.7
... A244: 45747 | B244: 104,9 | C244: =B244*1 -> 104.9

Sheet Interest Rate
A1: Data | B1: Zamkniecie | C1: Zamkniecie2
A2: 35854 | B2: 24 | C2: =inrtpl_m_m[[#This Row],[Zamkniecie]]*1 -> 24
A3: 35915 | B3: 23 | C3: =inrtpl_m_m[[#This Row],[Zamkniecie]]*1 -> 23
A4: 35946 | B4: 21.5 | C4: =inrtpl_m_m[[#This Row],[Zamkniecie]]*1 -> 21.5
A5: 36007 | B5: 19 | C5: =inrtpl_m_m[[#This Row],[Zamkniecie]]*1 -> 19
A6: 36068 | B6: 18 | C6: =inrtpl_m_m[[#This Row],[Zamkniecie]]*1 -> 18
A7: 36099 | B7: 17 | C7: =inrtpl_m_m[[#This Row],[Zamkniecie]]*1 -> 17
A8: 36160 | B8: 15.5 | C8: =inrtpl_m_m[[#This Row],[Zamkniecie]]*1 -> 15.5
A9: 36191 | B9: 13 | C9: =inrtpl_m_m[[#This Row],[Zamkniecie]]*1 -> 13
A10: 36433 | B10: 14 | C10: =inrtpl_m_m[[#This Row],[Zamkniecie]]*1 -> 14
A11: 36494 | B11: 16.5 | C11: =inrtpl_m_m[[#This Row],[Zamkniecie]]*1 -> 16.5
A12: 36585 | B12: 17.5 | C12: =inrtpl_m_m[[#This Row],[Zamkniecie]]*1 -> 17.5
A13: 36769 | B13: 19 | C13: =inrtpl_m_m[[#This Row],[Zamkniecie]]*1 -> 19
A14: 36981 | B14: 17 | C14: =inrtpl_m_m[[#This Row],[Zamkniecie]]*1 -> 17
A15: 37072 | B15: 15.5 | C15: =inrtpl_m_m[[#This Row],[Zamkniecie]]*1 -> 15.5
A16: 37134 | B16: 14.5 | C16: =inrtpl_m_m[[#This Row],[Zamkniecie]]*1 -> 14.5
A17: 37195 | B17: 13 | C17: =inrtpl_m_m[[#This Row],[Zamkniecie]]*1 -> 13
A18: 37225 | B18: 11.5 | C18: =inrtpl_m_m[[#This Row],[Zamkniecie]]*1 -> 11.5
A19: 37256 | B19: 11.5 | C19: =inrtpl_m_m[[#This Row],[Zamkniecie]]*1 -> 11.5
A20: 37287 | B20: 10 | C20: =inrtpl_m_m[[#This Row],[Zamkniecie]]*1 -> 10
A21: 37376 | B21: 9.5 | C21: =inrtpl_m_m[[#This Row],[Zamkniecie]]*1 -> 9.5
A22: 37407 | B22: 9 | C22: =inrtpl_m_m[[#This Row],[Zamkniecie]]*1 -> 9
A23: 37437 | B23: 8.5 | C23: =inrtpl_m_m[[#This Row],[Zamkniecie]]*1 -> 8.5
A24: 37499 | B24: 8 | C24: =inrtpl_m_m[[#This Row],[Zamkniecie]]*1 -> 8
A25: 37529 | B25: 7.5 | C25: =inrtpl_m_m[[#This Row],[Zamkniecie]]*1 -> 7.5
A26: 37560 | B26: 7 | C26: =inrtpl_m_m[[#This Row],[Zamkniecie]]*1 -> 7
A27: 37590 | B27: 6.75 | C27: =inrtpl_m_m[[#This Row],[Zamkniecie]]*1 -> 6.75
A28: 37652 | B28: 6.5 | C28: =inrtpl_m_m[[#This Row],[Zamkniecie]]*1 -> 6.5
A29: 37680 | B29: 6.25 | C29: =inrtpl_m_m[[#This Row],[Zamkniecie]]*1 -> 6.25
A30: 37711 | B30: 6 | C30: =inrtpl_m_m[[#This Row],[Zamkniecie]]*1 -> 6
A31: 37741 | B31: 5.75 | C31: =inrtpl_m_m[[#This Row],[Zamkniecie]]*1 -> 5.75
A32: 37772 | B32: 5.5 | C32: =inrtpl_m_m[[#This Row],[Zamkniecie]]*1 -> 5.5
A33: 37802 | B33: 5.25 | C33: =inrtpl_m_m[[#This Row],[Zamkniecie]]*1 -> 5.25
A34: 38199 | B34: 6 | C34: =inrtpl_m_m[[#This Row],[Zamkniecie]]*1 -> 6
A35: 38230 | B35: 6.5 | C35: =inrtpl_m_m[[#This Row],[Zamkniecie]]*1 -> 6.5
A36: 38442 | B36: 6 | C36: =inrtpl_m_m[[#This Row],[Zamkniecie]]*1 -> 6
A37: 38472 | B37: 5.5 | C37: =inrtpl_m_m[[#This Row],[Zamkniecie]]*1 -> 5.5
A38: 38533 | B38: 5 | C38: =inrtpl_m_m[[#This Row],[Zamkniecie]]*1 -> 5
A39: 38564 | B39: 4.75 | C39: =inrtpl_m_m[[#This Row],[Zamkniecie]]*1 -> 4.75
A40: 38625 | B40: 4.5 | C40: =inrtpl_m_m[[#This Row],[Zamkniecie]]*1 -> 4.5
...

Sheet M2
A1: Data | B1: M2
A2: 35430 | B2: 140038.73
A3: 35461 | B3: 138755.53
A4: 35489 | B4: 141142.53
A5: 35520 | B5: 144080.77
A6: 35550 | B6: 147471.79
A7: 35581 | B7: 151110.56
A8: 35611 | B8: 154073.61
A9: 35642 | B9: 160056.31
A10: 35673 | B10: 162082.22
A11: 35703 | B11: 164710.23
A12: 35734 | B12: 169848.85
A13: 35764 | B13: 173093.79
... A341: 45747 | B341: 2504139.7

Sheet Industry Production
A1: Data | B1: Produkcja przemysłowa | C1: Produkcja przemysłowa
A2: 38383 | B2: 100 | C2: =B2*1 -> 100 | D2: =C2-100 -> 0
A3: 38411 | B3: 100,0 | C3: =B3*1 -> 100 | D3: =C3-100 -> 0
A4: 38442 | B4: 109,5 | C4: =B4*1 -> 109.5 | D4: =C4-100 -> 9.5
A5: 38472 | B5: 99,1 | C5: =B5*1 -> 99.1 | D5: =C5-100 -> -0.9
A6: 38503 | B6: 95,1 | C6: =B6*1 -> 95.1 | D6: =C6-100 -> -4.9
A7: 38533 | B7: 108,7 | C7: =B7*1 -> 108.7 | D7: =C7-100 -> 8.7
A8: 38564 | B8: 92,3 | C8: =B8*1 -> 92.3 | D8: =C8-100 -> -7.7
A9: 38595 | B9: 104,1 | C9: =B9*1 -> 104.1 | D9: =C9-100 -> 4.1
A10: 38625 | B10: 109,9 | C10: =B10*1 -> 109.9 | D10: =C10-100 -> 9.9
A11: 38656 | B11: 101,8 | C11: =B11*1 -> 101.8 | D11: =C11-100 -> 1.8
A12: 38686 | B12: 100,0 | C12: =B12*1 -> 100 | D12: =C12-100 -> 0
A13: 38717 | B13: 98,2 | C13: =B13*1 -> 98.2 | D13: =C13-100 -> -1.8
A14: 38748 | B14: 93,2 | C14: =B14*1 -> 93.2 | D14: =C14-100 -> -6.8
... A244: 45747 | B244: 108,6 | C244: =B244*1 -> 108.6 | D244: =C244-100 -> 8.6

Sheet Import Export
A1: Data | B1: Import | C1: Export | D1: Import | E1: Export
A2: 36556 | B2: 14 440,8 | C2: 9341,3 | D2: =B2*1 -> 14440.8 | E2: =C2*1 -> 9341.3
A3: 36585 | B3: 16 351,6 | C3: 10 647,4 | D3: =B3*1 -> 16351.6 | E3: =C3*1 -> 10647.4
A4: 36616 | B4: 17 884,3 | C4: 11 228,3 | D4: =B4*1 -> 17884.3 | E4: =C4*1 -> 11228.3
A5: 36646 | B5: 16 446,1 | C5: 10 471,2 | D5: =B5*1 -> 16446.1 | E5: =C5*1 -> 10471.2
A6: 36677 | B6: 19 171,6 | C6: 10 908,7 | D6: =B6*1 -> 19171.6 | E6: =C6*1 -> 10908.7
A7: 36707 | B7: 17 958,6 | C7: 11 470,9 | D7: =B7*1 -> 17958.6 | E7: =C7*1 -> 11470.9
A8: 36738 | B8: 17 786,4 | C8: 11 550,4 | D8: =B8*1 -> 17786.4 | E8: =C8*1 -> 11550.4
A9: 36769 | B9: 16 692,8 | C9: 11 193,9 | D9: =B9*1 -> 16692.8 | E9: =C9*1 -> 11193.9
A10: 36799 | B10: 18 052,1 | C10: 12 367,8 | D10: =B10*1 -> 18052.1 | E10: =C10*1 -> 12367.8
A11: 36830 | B11: 20 579,6 | C11: 13 605,1 | D11: =B11*1 -> 20579.6 | E11: =C11*1 -> 13605.1
A12: 36860 | B12: 19 130,9 | C12: 13 118,5 | D12: =B12*1 -> 19130.9 | E12: =C12*1 -> 13118.5
A13: 36891 | B13: 18 577,0 | C13: 12 005,2 | D13: =B13*1 -> 18577 | E13: =C13*1 -> 12005.2
... A303: 45716 | B303: 119 018,1 | C303: 115 935,4 | D303: =B303*1 -> 119018.1 | E303: =C303*1 -> 115935.4

Sheet USDPLN
A1: Data | B1: Zamkniecie
A2: 30712 | B2: 0.0099
A3: 30741 | B3: 0.0098
A4: 30772 | B4: 0.0109
A5: 30802 | B5: 0.011
A6: 30833 | B6: 0.0111
A7: 30863 | B7: 0.0111
A8: 30894 | B8: 0.0113
A9: 30925 | B9: 0.0113
A10: 30955 | B10: 0.0126
A11: 30986 | B11: 0.0126
A12: 31016 | B12: 0.0125
A13: 31047 | B13: 0.0126
... A498: 45808 | B498: 3.76008

Sheet Foreign Reservs
A1: Data | B1: Rezerwy USD
A2: 35826 | B2: 22091.1
A3: 35854 | B3: 24279.3
A4: 35885 | B4: 24400.6
A5: 35915 | B5: 25922.9
A6: 35946 | B6: 26286.1
A7: 35976 | B7: 27120.8
A8: 36007 | B8: 29541.4
A9: 36038 | B9: 29519.6
A10: 36068 | B10: 28104.6
A11: 36099 | B11: 28516.9
A12: 36129 | B12: 28660.8
A13: 36160 | B13: 28275.1
... A329: 45777 | B329: 242430
